[2022-08-14 11:53:08,662] logger_util.py->write_log line:65 [INFO] ------------------------接口请求开始-------------------------
[2022-08-14 11:53:08,663] logger_util.py->write_log line:65 [INFO] 接口名称：发送整数：1adf
[2022-08-14 11:53:08,663] logger_util.py->write_log line:65 [INFO] 请求头：None
[2022-08-14 11:53:08,663] logger_util.py->write_log line:65 [INFO] 请求路径：/superAdmin/user-manage/give-adfun
[2022-08-14 11:53:08,663] logger_util.py->write_log line:65 [INFO] 接口替换前的请求数据：{'uid': '143', 'amount': '1', 'reason': '测试发放整数'}
[2022-08-14 11:53:09,250] logger_util.py->write_log line:65 [INFO] ------------------默认返回的响应结果是字典，调用result_validate方法断言-------------------
[2022-08-14 11:53:09,250] logger_util.py->write_log line:65 [INFO] 预期结果：[{'equals': {'return_code': 'SUCCESS'}}]
[2022-08-14 11:53:09,250] logger_util.py->write_log line:65 [INFO] 实际结果：{'return_code': 'SUCCESS', 'return_msg': '22081411530872851512'}
[2022-08-14 11:53:09,250] logger_util.py->write_log line:65 [INFO] 接口执行成功
[2022-08-14 11:53:09,250] logger_util.py->write_log line:65 [INFO] ------------------------接口请求结束-------------------------

[2022-08-14 11:53:09,256] logger_util.py->write_log line:65 [INFO] ------------------------接口请求开始-------------------------
[2022-08-14 11:53:09,256] logger_util.py->write_log line:65 [INFO] 接口名称：发送一位小数：0.1adf
[2022-08-14 11:53:09,256] logger_util.py->write_log line:65 [INFO] 请求头：None
[2022-08-14 11:53:09,256] logger_util.py->write_log line:65 [INFO] 请求路径：/superAdmin/user-manage/give-adfun
[2022-08-14 11:53:09,256] logger_util.py->write_log line:65 [INFO] 接口替换前的请求数据：{'uid': '143', 'amount': '0.1', 'reason': '发送一位小数'}
[2022-08-14 11:53:09,855] logger_util.py->write_log line:65 [INFO] ------------------默认返回的响应结果是字典，调用result_validate方法断言-------------------
[2022-08-14 11:53:09,856] logger_util.py->write_log line:65 [INFO] 预期结果：[{'equals': {'return_code': 'SUCCESS'}}]
[2022-08-14 11:53:09,856] logger_util.py->write_log line:65 [INFO] 实际结果：{'return_code': 'SUCCESS', 'return_msg': '2208141153093415151729'}
[2022-08-14 11:53:09,856] logger_util.py->write_log line:65 [INFO] 接口执行成功
[2022-08-14 11:53:09,856] logger_util.py->write_log line:65 [INFO] ------------------------接口请求结束-------------------------

[2022-08-14 11:53:09,861] logger_util.py->write_log line:65 [INFO] ------------------------接口请求开始-------------------------
[2022-08-14 11:53:09,862] logger_util.py->write_log line:65 [INFO] 接口名称：发送两位小数：0.01adf
[2022-08-14 11:53:09,862] logger_util.py->write_log line:65 [INFO] 请求头：None
[2022-08-14 11:53:09,862] logger_util.py->write_log line:65 [INFO] 请求路径：/superAdmin/user-manage/give-adfun
[2022-08-14 11:53:09,862] logger_util.py->write_log line:65 [INFO] 接口替换前的请求数据：{'uid': '143', 'amount': '0.01', 'reason': '发送两位小数'}
[2022-08-14 11:53:10,550] logger_util.py->write_log line:65 [INFO] ------------------默认返回的响应结果是字典，调用result_validate方法断言-------------------
[2022-08-14 11:53:10,550] logger_util.py->write_log line:65 [INFO] 预期结果：[{'equals': {'return_code': 'SUCCESS'}}]
[2022-08-14 11:53:10,550] logger_util.py->write_log line:65 [INFO] 实际结果：{'return_code': 'SUCCESS', 'return_msg': '2208141153099015151697'}
[2022-08-14 11:53:10,550] logger_util.py->write_log line:65 [INFO] 接口执行成功
[2022-08-14 11:53:10,550] logger_util.py->write_log line:65 [INFO] ------------------------接口请求结束-------------------------

[2022-08-14 11:53:10,556] logger_util.py->write_log line:65 [INFO] ------------------------接口请求开始-------------------------
[2022-08-14 11:53:10,556] logger_util.py->write_log line:65 [INFO] 接口名称：发送数据为空
[2022-08-14 11:53:10,556] logger_util.py->write_log line:65 [INFO] 请求头：None
[2022-08-14 11:53:10,556] logger_util.py->write_log line:65 [INFO] 请求路径：/superAdmin/user-manage/give-adfun
[2022-08-14 11:53:10,556] logger_util.py->write_log line:65 [INFO] 接口替换前的请求数据：{'uid': '143', 'amount': '', 'reason': '发送两位小数'}
[2022-08-14 11:53:10,749] logger_util.py->write_log line:65 [INFO] ------------------默认返回的响应结果是字典，调用result_validate方法断言-------------------
[2022-08-14 11:53:10,749] logger_util.py->write_log line:65 [INFO] 预期结果：[{'equals': {'return_code': 'SUCCESS'}}]
[2022-08-14 11:53:10,750] logger_util.py->write_log line:65 [INFO] 实际结果：{'return_code': 'FAIL', 'return_msg': 'Amount不能为空。'}
[2022-08-14 11:53:10,750] logger_util.py->write_error_log line:69 [INFO] 断言失败，return_code断言失败！
[2022-08-14 11:53:10,750] logger_util.py->write_log line:65 [INFO] 接口执行失败
[2022-08-14 11:53:10,751] logger_util.py->write_error_log line:69 [INFO] 断言出错,异常信息：Traceback (most recent call last):
  File "C:\Users\pc\Desktop\aiduifen\common\requests_util.py", line 266, in result_validate
    write_error_log("断言失败，%s断言失败！" % assert_key)
  File "C:\Users\pc\Desktop\aiduifen\common\logger_util.py", line 70, in write_error_log
    raise Exception(log_message)
Exception: 断言失败，return_code断言失败！

[2022-08-14 11:53:10,751] logger_util.py->write_error_log line:69 [INFO] 分析yaml文件出错,异常信息：Traceback (most recent call last):
  File "C:\Users\pc\Desktop\aiduifen\common\requests_util.py", line 266, in result_validate
    write_error_log("断言失败，%s断言失败！" % assert_key)
  File "C:\Users\pc\Desktop\aiduifen\common\logger_util.py", line 70, in write_error_log
    raise Exception(log_message)
Exception: 断言失败，return_code断言失败！

During handling of the above exception, another exception occurred:

Traceback (most recent call last):
  File "C:\Users\pc\Desktop\aiduifen\common\requests_util.py", line 140, in analysis_yaml
    self.result_validate(yq_result=yq_result, real_result=res.json(), status_code=status_code)
  File "C:\Users\pc\Desktop\aiduifen\common\requests_util.py", line 290, in result_validate
    write_error_log("断言出错,异常信息：%s" % str(traceback.format_exc()))
  File "C:\Users\pc\Desktop\aiduifen\common\logger_util.py", line 70, in write_error_log
    raise Exception(log_message)
Exception: 断言出错,异常信息：Traceback (most recent call last):
  File "C:\Users\pc\Desktop\aiduifen\common\requests_util.py", line 266, in result_validate
    write_error_log("断言失败，%s断言失败！" % assert_key)
  File "C:\Users\pc\Desktop\aiduifen\common\logger_util.py", line 70, in write_error_log
    raise Exception(log_message)
Exception: 断言失败，return_code断言失败！


